<sdf version="1.9">
  <model name="MR_Buggy3">
    <pose>0 0 .04 0 0 0</pose>
    <self_collide>false</self_collide>
    <static>false</static>
    <link name="MR_Buggy3/Base">
      <inertial>
        <pose>0 0 0 0 0 0</pose>
        <mass>3.0</mass>
        <inertia>
          <ixx>0.0054</ixx>
          <ixy>0</ixy>
          <ixz>0</ixz>
          <iyy>0.0252</iyy>
          <iyz>0</iyz>
          <izz>0.0252</izz>
        </inertia>
      </inertial>
      <visual name="MR_Buggy3/BaseVisual">
        <pose>.1371 0 -.0115 -0.018 0 1.5707</pose>
        <geometry>
          <mesh>
            <uri>model://MR_Buggy3/meshes/BaseReduced.dae</uri>
          </mesh>
        </geometry>
      </visual>
      <visual name="MR_Buggy3/TopVisual">
        <pose>.1371 0 -.0115 -0.018 0 1.5707</pose>
        <geometry>
          <mesh>
            <uri>model://MR_Buggy3/meshes/TopReduced.dae</uri>
          </mesh>
        </geometry>
      </visual>
      <collision name="MR_Buggy3/BaseCollision">
        <pose>0 0 .06 0 0 0</pose>
        <geometry>
          <box>
            <size>.3 .09 .12</size>
          </box>
        </geometry>
      </collision>
    </link>
    <link name="MR_Buggy3/FrontRightWheel">
      <pose relative_to="MR_Buggy3/FrontRightWheelJoint">0 0 0 0 0 0</pose>
      <inertial>
        <mass>.05</mass>
        <inertia>
          <ixx>0.00003331</ixx>
          <ixy>0</ixy>
          <ixz>0</ixz>
          <iyy>0.0000204</iyy>
          <iyz>0</iyz>
          <izz>0.0000204</izz>
        </inertia>
      </inertial>
      <gravity>true</gravity>
      <velocity_decay/>
      <visual name="MR_Buggy3/FrontRightWheelVisual">
        <pose>0 0 0 0 0 0</pose>
        <geometry>
          <mesh>
            <uri>model://MR_Buggy3/meshes/Wheel.dae</uri>
          </mesh>
        </geometry>
      </visual>
      <collision name="MR_Buggy3/FrontRightWheelCollision">
        <pose>0 .015 0 -1.5707 0 0</pose>
        <geometry>
          <cylinder>
            <length>0.03</length>
            <radius>0.0365</radius>
          </cylinder>
        </geometry>
        <surface>
          <friction>
            <ode>
              <mu>1.0</mu>
              <mu2>0.5</mu2>
              <fdir1>0 0 1</fdir1>
            </ode>
          </friction>
        </surface>
      </collision>
    </link>
    <link name="MR_Buggy3/FrontRightWheelSteering">
      <pose relative_to="MR_Buggy3/FrontRightWheelSteeringJoint">0 0 0 0 0 0</pose>
      <inertial>
        <mass>0.005</mass>
        <inertia>
          <ixx>0.0000018</ixx>
          <iyy>0.0000018</iyy>
          <izz>0.0000018</izz>
        </inertia>
      </inertial>
    </link>
    <link name="MR_Buggy3/FrontLeftWheel">
      <pose relative_to="MR_Buggy3/FrontLeftWheelJoint">0 0 0 0 0 0</pose>
      <inertial>
        <mass>.05</mass>
        <inertia>
          <ixx>0.00003331</ixx>
          <ixy>0</ixy>
          <ixz>0</ixz>
          <iyy>0.0000204</iyy>
          <iyz>0</iyz>
          <izz>0.0000204</izz>
        </inertia>
      </inertial>
      <gravity>true</gravity>
      <velocity_decay/>
      <visual name="MR_Buggy3/FrontLeftWheelVisual">
        <pose>0 0 0 0 0 3.14159</pose>
        <geometry>
          <mesh>
            <uri>model://MR_Buggy3/meshes/Wheel.dae</uri>
          </mesh>
        </geometry>
      </visual>
      <collision name="MR_Buggy3/FrontLeftWheelCollision">
        <pose>0 -.015 0 -1.5707 0 0</pose>
        <geometry>
          <cylinder>
            <length>0.03</length>
            <radius>0.0365</radius>
          </cylinder>
        </geometry>
        <surface>
          <friction>
            <ode>
              <mu>1.0</mu>
              <mu2>0.5</mu2>
              <fdir1>0 0 1</fdir1>
            </ode>
          </friction>
        </surface>
      </collision>
    </link>
    <link name="MR_Buggy3/FrontLeftWheelSteering">
      <pose relative_to="MR_Buggy3/FrontLeftWheelSteeringJoint">0 0 0 0 0 0</pose>
      <inertial>
        <mass>0.005</mass>
        <inertia>
          <ixx>0.0000018</ixx>
          <iyy>0.0000018</iyy>
          <izz>0.0000018</izz>
        </inertia>
      </inertial>
    </link>
    <link name="MR_Buggy3/RearRightWheel">
      <pose relative_to="MR_Buggy3/RearRightWheelJoint">0 0 0 0 0 0</pose>
      <inertial>
        <mass>.05</mass>
        <inertia>
          <ixx>0.00003331</ixx>
          <ixy>0</ixy>
          <ixz>0</ixz>
          <iyy>0.0000204</iyy>
          <iyz>0</iyz>
          <izz>0.0000204</izz>
        </inertia>
      </inertial>
      <gravity>true</gravity>
      <velocity_decay/>
      <visual name="MR_Buggy3/RearRightWheelVisual">
        <pose>0 0 0 0 0 0</pose>
        <geometry>
          <mesh>
            <uri>model://MR_Buggy3/meshes/Wheel.dae</uri>
          </mesh>
        </geometry>
      </visual>
      <collision name="MR_Buggy3/RearRightWheelCollision">
        <pose>0 .015 0 -1.5707 0 0</pose>
        <geometry>
          <cylinder>
            <length>0.03</length>
            <radius>0.0365</radius>
          </cylinder>
        </geometry>
        <surface>
          <friction>
            <ode>
              <mu>1.0</mu>
              <mu2>0.5</mu2>
              <fdir1>0 0 1</fdir1>
            </ode>
          </friction>
        </surface>
      </collision>
    </link>
    <link name="MR_Buggy3/RearLeftWheel">
      <pose relative_to="MR_Buggy3/RearLeftWheelJoint">0 0 0 0 0 0</pose>
      <inertial>
        <mass>.05</mass>
        <inertia>
          <ixx>0.00003331</ixx>
          <ixy>0</ixy>
          <ixz>0</ixz>
          <iyy>0.0000204</iyy>
          <iyz>0</iyz>
          <izz>0.0000204</izz>
        </inertia>
      </inertial>
      <gravity>true</gravity>
      <velocity_decay/>
      <visual name="MR_Buggy3/RearLeftWheelVisual">
        <pose>0 0 0 0 0 3.14159</pose>
        <geometry>
          <mesh>
            <uri>model://MR_Buggy3/meshes/Wheel.dae</uri>
          </mesh>
        </geometry>
      </visual>
      <collision name="MR_Buggy3/RearLeftWheelCollision">
        <pose>0 -.015 0 -1.5707 0 0</pose>
        <geometry>
          <cylinder>
            <length>0.03</length>
            <radius>0.0365</radius>
          </cylinder>
        </geometry>
        <surface>
          <friction>
            <ode>
              <mu>1.0</mu>
              <mu2>0.5</mu2>
              <fdir1>0 0 1</fdir1>
            </ode>
          </friction>
        </surface>
      </collision>
    </link>
    <joint name="MR_Buggy3/FrontRightWheelSteeringJoint" type="revolute">
      <parent>MR_Buggy3/Base</parent>
      <child>MR_Buggy3/FrontRightWheelSteering</child>
      <pose relative_to="MR_Buggy3/Base">.112 -.10 0 0 0 0</pose>
      <axis>
        <xyz>0 0 1</xyz>
        <limit>
          <lower>-0.49</lower>
          <upper>0.49</upper>
          <velocity>1.0</velocity>
          <effort>200</effort>
        </limit>
        <use_parent_model_frame>1</use_parent_model_frame>
      </axis>
    </joint>
    <joint name="MR_Buggy3/FrontRightWheelJoint" type="revolute">
      <parent>MR_Buggy3/FrontRightWheelSteering</parent>
      <child>MR_Buggy3/FrontRightWheel</child>
      <pose relative_to="MR_Buggy3/FrontRightWheelSteeringJoint">0 0 0 0 0 0</pose>
      <axis>
        <xyz>0 1 0</xyz>
        <limit>
          <lower>-1.79769e+308</lower>
          <upper>1.79769e+308</upper>
        </limit>
        <dynamics>
          <spring_reference>0</spring_reference>
          <spring_stiffness>0</spring_stiffness>
        </dynamics>
        <use_parent_model_frame>1</use_parent_model_frame>
      </axis>
    </joint>
    <joint name="MR_Buggy3/FrontLeftWheelSteeringJoint" type="revolute">
      <parent>MR_Buggy3/Base</parent>
      <child>MR_Buggy3/FrontLeftWheelSteering</child>
      <pose relative_to="MR_Buggy3/Base">.112 .10 0 0 0 0</pose>
      <axis>
        <xyz>0 0 1</xyz>
        <limit>
          <lower>-0.49</lower>
          <upper>0.49</upper>
          <velocity>1.0</velocity>
          <effort>200</effort>
        </limit>
        <use_parent_model_frame>1</use_parent_model_frame>
      </axis>
    </joint>
    <joint name="MR_Buggy3/FrontLeftWheelJoint" type="revolute">
      <parent>MR_Buggy3/FrontLeftWheelSteering</parent>
      <child>MR_Buggy3/FrontLeftWheel</child>
      <pose relative_to="MR_Buggy3/FrontLeftWheelSteeringJoint">0 0 0 0 0 0</pose>
      <axis>
        <xyz>0 1 0</xyz>
        <limit>
          <lower>-1.79769e+308</lower>
          <upper>1.79769e+308</upper>
        </limit>
        <dynamics>
          <spring_reference>0</spring_reference>
          <spring_stiffness>0</spring_stiffness>
        </dynamics>
        <use_parent_model_frame>1</use_parent_model_frame>
      </axis>
    </joint>
    <joint name="MR_Buggy3/RearRightWheelJoint" type="revolute">
      <parent>MR_Buggy3/Base</parent>
      <child>MR_Buggy3/RearRightWheel</child>
      <pose relative_to="MR_Buggy3/Base">-.1135 -.10 0 0 0 0</pose>
      <axis>
        <xyz>0 1 0</xyz>
        <limit>
          <lower>-1.79769e+308</lower>
          <upper>1.79769e+308</upper>
        </limit>
        <dynamics>
          <spring_reference>0</spring_reference>
          <spring_stiffness>0</spring_stiffness>
        </dynamics>
        <use_parent_model_frame>1</use_parent_model_frame>
      </axis>
    </joint>
    <joint name="MR_Buggy3/RearLeftWheelJoint" type="revolute">
      <parent>MR_Buggy3/Base</parent>
      <child>MR_Buggy3/RearLeftWheel</child>
      <pose relative_to="MR_Buggy3/Base">-.1135 .10 0 0 0 0</pose>
      <axis>
        <xyz>0 1 0</xyz>
        <limit>
          <lower>-1.79769e+308</lower>
          <upper>1.79769e+308</upper>
        </limit>
        <dynamics>
          <spring_reference>0</spring_reference>
          <spring_stiffness>0</spring_stiffness>
        </dynamics>
        <use_parent_model_frame>1</use_parent_model_frame>
      </axis>
    </joint>
    <plugin
        filename="gz-sim-joint-controller-system"
        name="gz::sim::systems::JointController">
      <joint_name>MR_Buggy3/FrontLeftWheelJoint</joint_name>
      <joint_name>MR_Buggy3/FrontRightWheelJoint</joint_name>
      <joint_name>MR_Buggy3/RearRightWheelJoint</joint_name>
      <joint_name>MR_Buggy3/RearLeftWheelJoint</joint_name>
      <sub_topic>drive</sub_topic>
    </plugin>
    <!-- <plugin
        filename="gz-sim-joint-position-controller-system"
        name="gz::sim::systems::JointPositionController">
      <joint_name>MR_Buggy3/FrontRightWheelSteeringJoint</joint_name>
      <joint_name>MR_Buggy3/FrontLeftWheelSteeringJoint</joint_name>
      <sub_topic>steer_angle</sub_topic>
    </plugin> -->
     <plugin
      filename="gz-sim-ackermann-steering-system"
      name="gz::sim::systems::AckermannSteering">
      <steering_only>true</steering_only>
      <left_steering_joint>MR_Buggy3/FrontLeftWheelSteeringJoint</left_steering_joint>
      <right_steering_joint>MR_Buggy3/FrontRightWheelSteeringJoint</right_steering_joint>
      <steering_limit>0.4</steering_limit>
      <wheel_base>.2255</wheel_base>
      <wheel_separation>.2</wheel_separation>
    </plugin>
<!--    <plugin
      filename="gz-sim-ackermann-steering-system"
      name="gz::sim::systems::AckermannSteering">
      <left_joint>MR_Buggy3/FrontLeftWheelJoint</left_joint>
      <left_joint>MR_Buggy3/RearLeftWheelJoint</left_joint>
      <right_joint>MR_Buggy3/FrontRightWheelJoint</right_joint>
      <right_joint>MR_Buggy3/FrontRightWheelJoint</right_joint>
      <left_steering_joint>MR_Buggy3/FrontLeftWheelSteeringJoint</left_steering_joint>
      <right_steering_joint>MR_Buggy3/FrontRightWheelSteeringJoint</right_steering_joint>
      <kingpin_width>.18</kingpin_width>
      <steering_limit>0.5</steering_limit>
      <wheel_base>.2255</wheel_base>
      <wheel_separation>.2</wheel_separation>
      <wheel_radius>0.0365</wheel_radius>
      <min_velocity>-100</min_velocity>
      <max_velocity>100</max_velocity>
      <min_acceleration>-5</min_acceleration>
      <max_acceleration>5</max_acceleration>
      <topic>/cmd_vel</topic>
    </plugin> -->
  </model>
</sdf>
